data/sample_lob.csv
timestamp,order_id,side,price,quantity,action
0,seed_bid,BUY,99.0,100,ADD
0,seed_ask,SELL,101.0,100,ADD
1,o1,BUY,100.0,10,ADD
1,o2,SELL,101.0,10,ADD
2,o3,BUY,99.5,5,ADD
2,o4,SELL,100.5,5,ADD
3,o5,BUY,101.0,20,ADD
3,o6,SELL,99.0,20,ADD
4,o3,,0,0,CANCEL
5,o7,BUY,100.2,15,ADD
5,o8,SELL,100.8,15,ADD
6,o9,SELL,99.5,50,ADD
7,o10,BUY,100.5,30,ADD
8,o11,SELL,100.0,10,ADD
9,o12,BUY,101.5,25,ADD
10,o13,SELL,99.5,25,ADD
